/home/stas/NotOnlyFansBot/venv/lib/python3.10/site-packages/grequests.py:22: MonkeyPatchWarning: Monkey-patching ssl after ssl has already been imported may lead to errors, including RecursionError on Python 3.6. It may also silently lead to incorrect behaviour on Python 3.7. Please monkey-patch earlier. See https://github.com/gevent/gevent/issues/1016. Modules that had direct imports (NOT patched): ['aiohttp.connector (/home/stas/NotOnlyFansBot/venv/lib/python3.10/site-packages/aiohttp/connector.py)', 'aiohttp.client (/home/stas/NotOnlyFansBot/venv/lib/python3.10/site-packages/aiohttp/client.py)', 'aiohttp.client_exceptions (/home/stas/NotOnlyFansBot/venv/lib/python3.10/site-packages/aiohttp/client_exceptions.py)', 'aiohttp.web (/home/stas/NotOnlyFansBot/venv/lib/python3.10/site-packages/aiohttp/web.py)', 'aiohttp.client_reqrep (/home/stas/NotOnlyFansBot/venv/lib/python3.10/site-packages/aiohttp/client_reqrep.py)', 'aiohttp.web_runner (/home/stas/NotOnlyFansBot/venv/lib/python3.10/site-packages/aiohttp/web_runner.py)']. 
  curious_george.patch_all(thread=False, select=False)
2023-09-12 23:49:09,420 - INFO - executor.py:362 - Bot: NotOnlyFans [@NonOnlyFansBot]
2023-09-12 23:49:09,525 - WARNING - executor.py:358 - Updates were skipped successfully.
2023-09-12 23:49:09,525 - INFO - dispatcher.py:358 - Start polling.
2023-09-12 23:49:14,692 - ERROR - dispatcher.py:390 - Cause exception while getting updates.
Traceback (most recent call last):
  File "/home/stas/NotOnlyFansBot/venv/lib/python3.10/site-packages/aiogram/dispatcher/dispatcher.py", line 381, in start_polling
    updates = await self.bot.get_updates(
  File "/home/stas/NotOnlyFansBot/venv/lib/python3.10/site-packages/aiogram/bot/bot.py", line 110, in get_updates
    result = await self.request(api.Methods.GET_UPDATES, payload)
  File "/home/stas/NotOnlyFansBot/venv/lib/python3.10/site-packages/aiogram/bot/base.py", line 236, in request
    return await api.make_request(await self.get_session(), self.server, self.__token, method, data, files,
  File "/home/stas/NotOnlyFansBot/venv/lib/python3.10/site-packages/aiogram/bot/api.py", line 140, in make_request
    return check_result(method, response.content_type, response.status, await response.text())
  File "/home/stas/NotOnlyFansBot/venv/lib/python3.10/site-packages/aiogram/bot/api.py", line 119, in check_result
    exceptions.ConflictError.detect(description)
  File "/home/stas/NotOnlyFansBot/venv/lib/python3.10/site-packages/aiogram/utils/exceptions.py", line 140, in detect
    raise err(cls.text or description)
aiogram.utils.exceptions.TerminatedByOtherGetUpdates: Terminated by other getupdates request; make sure that only one bot instance is running
2023-09-12 23:49:24,809 - ERROR - dispatcher.py:390 - Cause exception while getting updates.
Traceback (most recent call last):
  File "/home/stas/NotOnlyFansBot/venv/lib/python3.10/site-packages/aiogram/dispatcher/dispatcher.py", line 381, in start_polling
    updates = await self.bot.get_updates(
  File "/home/stas/NotOnlyFansBot/venv/lib/python3.10/site-packages/aiogram/bot/bot.py", line 110, in get_updates
    result = await self.request(api.Methods.GET_UPDATES, payload)
  File "/home/stas/NotOnlyFansBot/venv/lib/python3.10/site-packages/aiogram/bot/base.py", line 236, in request
    return await api.make_request(await self.get_session(), self.server, self.__token, method, data, files,
  File "/home/stas/NotOnlyFansBot/venv/lib/python3.10/site-packages/aiogram/bot/api.py", line 140, in make_request
    return check_result(method, response.content_type, response.status, await response.text())
  File "/home/stas/NotOnlyFansBot/venv/lib/python3.10/site-packages/aiogram/bot/api.py", line 119, in check_result
    exceptions.ConflictError.detect(description)
  File "/home/stas/NotOnlyFansBot/venv/lib/python3.10/site-packages/aiogram/utils/exceptions.py", line 140, in detect
    raise err(cls.text or description)
aiogram.utils.exceptions.TerminatedByOtherGetUpdates: Terminated by other getupdates request; make sure that only one bot instance is running
2023-09-12 23:49:34,929 - ERROR - dispatcher.py:390 - Cause exception while getting updates.
Traceback (most recent call last):
  File "/home/stas/NotOnlyFansBot/venv/lib/python3.10/site-packages/aiogram/dispatcher/dispatcher.py", line 381, in start_polling
    updates = await self.bot.get_updates(
  File "/home/stas/NotOnlyFansBot/venv/lib/python3.10/site-packages/aiogram/bot/bot.py", line 110, in get_updates
    result = await self.request(api.Methods.GET_UPDATES, payload)
  File "/home/stas/NotOnlyFansBot/venv/lib/python3.10/site-packages/aiogram/bot/base.py", line 236, in request
    return await api.make_request(await self.get_session(), self.server, self.__token, method, data, files,
  File "/home/stas/NotOnlyFansBot/venv/lib/python3.10/site-packages/aiogram/bot/api.py", line 140, in make_request
    return check_result(method, response.content_type, response.status, await response.text())
  File "/home/stas/NotOnlyFansBot/venv/lib/python3.10/site-packages/aiogram/bot/api.py", line 119, in check_result
    exceptions.ConflictError.detect(description)
  File "/home/stas/NotOnlyFansBot/venv/lib/python3.10/site-packages/aiogram/utils/exceptions.py", line 140, in detect
    raise err(cls.text or description)
aiogram.utils.exceptions.TerminatedByOtherGetUpdates: Terminated by other getupdates request; make sure that only one bot instance is running
2023-09-12 23:49:45,049 - ERROR - dispatcher.py:390 - Cause exception while getting updates.
Traceback (most recent call last):
  File "/home/stas/NotOnlyFansBot/venv/lib/python3.10/site-packages/aiogram/dispatcher/dispatcher.py", line 381, in start_polling
    updates = await self.bot.get_updates(
  File "/home/stas/NotOnlyFansBot/venv/lib/python3.10/site-packages/aiogram/bot/bot.py", line 110, in get_updates
    result = await self.request(api.Methods.GET_UPDATES, payload)
  File "/home/stas/NotOnlyFansBot/venv/lib/python3.10/site-packages/aiogram/bot/base.py", line 236, in request
    return await api.make_request(await self.get_session(), self.server, self.__token, method, data, files,
  File "/home/stas/NotOnlyFansBot/venv/lib/python3.10/site-packages/aiogram/bot/api.py", line 140, in make_request
    return check_result(method, response.content_type, response.status, await response.text())
  File "/home/stas/NotOnlyFansBot/venv/lib/python3.10/site-packages/aiogram/bot/api.py", line 119, in check_result
    exceptions.ConflictError.detect(description)
  File "/home/stas/NotOnlyFansBot/venv/lib/python3.10/site-packages/aiogram/utils/exceptions.py", line 140, in detect
    raise err(cls.text or description)
aiogram.utils.exceptions.TerminatedByOtherGetUpdates: Terminated by other getupdates request; make sure that only one bot instance is running
2023-09-12 23:49:55,177 - ERROR - dispatcher.py:390 - Cause exception while getting updates.
Traceback (most recent call last):
  File "/home/stas/NotOnlyFansBot/venv/lib/python3.10/site-packages/aiogram/dispatcher/dispatcher.py", line 381, in start_polling
    updates = await self.bot.get_updates(
  File "/home/stas/NotOnlyFansBot/venv/lib/python3.10/site-packages/aiogram/bot/bot.py", line 110, in get_updates
    result = await self.request(api.Methods.GET_UPDATES, payload)
  File "/home/stas/NotOnlyFansBot/venv/lib/python3.10/site-packages/aiogram/bot/base.py", line 236, in request
    return await api.make_request(await self.get_session(), self.server, self.__token, method, data, files,
  File "/home/stas/NotOnlyFansBot/venv/lib/python3.10/site-packages/aiogram/bot/api.py", line 140, in make_request
    return check_result(method, response.content_type, response.status, await response.text())
  File "/home/stas/NotOnlyFansBot/venv/lib/python3.10/site-packages/aiogram/bot/api.py", line 119, in check_result
    exceptions.ConflictError.detect(description)
  File "/home/stas/NotOnlyFansBot/venv/lib/python3.10/site-packages/aiogram/utils/exceptions.py", line 140, in detect
    raise err(cls.text or description)
aiogram.utils.exceptions.TerminatedByOtherGetUpdates: Terminated by other getupdates request; make sure that only one bot instance is running
2023-09-12 23:50:05,296 - ERROR - dispatcher.py:390 - Cause exception while getting updates.
Traceback (most recent call last):
  File "/home/stas/NotOnlyFansBot/venv/lib/python3.10/site-packages/aiogram/dispatcher/dispatcher.py", line 381, in start_polling
    updates = await self.bot.get_updates(
  File "/home/stas/NotOnlyFansBot/venv/lib/python3.10/site-packages/aiogram/bot/bot.py", line 110, in get_updates
    result = await self.request(api.Methods.GET_UPDATES, payload)
  File "/home/stas/NotOnlyFansBot/venv/lib/python3.10/site-packages/aiogram/bot/base.py", line 236, in request
    return await api.make_request(await self.get_session(), self.server, self.__token, method, data, files,
  File "/home/stas/NotOnlyFansBot/venv/lib/python3.10/site-packages/aiogram/bot/api.py", line 140, in make_request
    return check_result(method, response.content_type, response.status, await response.text())
  File "/home/stas/NotOnlyFansBot/venv/lib/python3.10/site-packages/aiogram/bot/api.py", line 119, in check_result
    exceptions.ConflictError.detect(description)
  File "/home/stas/NotOnlyFansBot/venv/lib/python3.10/site-packages/aiogram/utils/exceptions.py", line 140, in detect
    raise err(cls.text or description)
aiogram.utils.exceptions.TerminatedByOtherGetUpdates: Terminated by other getupdates request; make sure that only one bot instance is running
2023-09-12 23:50:11,395 - ERROR - dispatcher.py:390 - Cause exception while getting updates.
Traceback (most recent call last):
  File "/home/stas/NotOnlyFansBot/venv/lib/python3.10/site-packages/aiogram/dispatcher/dispatcher.py", line 381, in start_polling
    updates = await self.bot.get_updates(
  File "/home/stas/NotOnlyFansBot/venv/lib/python3.10/site-packages/aiogram/bot/bot.py", line 110, in get_updates
    result = await self.request(api.Methods.GET_UPDATES, payload)
  File "/home/stas/NotOnlyFansBot/venv/lib/python3.10/site-packages/aiogram/bot/base.py", line 236, in request
    return await api.make_request(await self.get_session(), self.server, self.__token, method, data, files,
  File "/home/stas/NotOnlyFansBot/venv/lib/python3.10/site-packages/aiogram/bot/api.py", line 140, in make_request
    return check_result(method, response.content_type, response.status, await response.text())
  File "/home/stas/NotOnlyFansBot/venv/lib/python3.10/site-packages/aiogram/bot/api.py", line 119, in check_result
    exceptions.ConflictError.detect(description)
  File "/home/stas/NotOnlyFansBot/venv/lib/python3.10/site-packages/aiogram/utils/exceptions.py", line 140, in detect
    raise err(cls.text or description)
aiogram.utils.exceptions.TerminatedByOtherGetUpdates: Terminated by other getupdates request; make sure that only one bot instance is running
2023-09-12 23:50:21,515 - ERROR - dispatcher.py:390 - Cause exception while getting updates.
Traceback (most recent call last):
  File "/home/stas/NotOnlyFansBot/venv/lib/python3.10/site-packages/aiogram/dispatcher/dispatcher.py", line 381, in start_polling
    updates = await self.bot.get_updates(
  File "/home/stas/NotOnlyFansBot/venv/lib/python3.10/site-packages/aiogram/bot/bot.py", line 110, in get_updates
    result = await self.request(api.Methods.GET_UPDATES, payload)
  File "/home/stas/NotOnlyFansBot/venv/lib/python3.10/site-packages/aiogram/bot/base.py", line 236, in request
    return await api.make_request(await self.get_session(), self.server, self.__token, method, data, files,
  File "/home/stas/NotOnlyFansBot/venv/lib/python3.10/site-packages/aiogram/bot/api.py", line 140, in make_request
    return check_result(method, response.content_type, response.status, await response.text())
  File "/home/stas/NotOnlyFansBot/venv/lib/python3.10/site-packages/aiogram/bot/api.py", line 119, in check_result
    exceptions.ConflictError.detect(description)
  File "/home/stas/NotOnlyFansBot/venv/lib/python3.10/site-packages/aiogram/utils/exceptions.py", line 140, in detect
    raise err(cls.text or description)
aiogram.utils.exceptions.TerminatedByOtherGetUpdates: Terminated by other getupdates request; make sure that only one bot instance is running
2023-09-12 23:50:31,636 - ERROR - dispatcher.py:390 - Cause exception while getting updates.
Traceback (most recent call last):
  File "/home/stas/NotOnlyFansBot/venv/lib/python3.10/site-packages/aiogram/dispatcher/dispatcher.py", line 381, in start_polling
    updates = await self.bot.get_updates(
  File "/home/stas/NotOnlyFansBot/venv/lib/python3.10/site-packages/aiogram/bot/bot.py", line 110, in get_updates
    result = await self.request(api.Methods.GET_UPDATES, payload)
  File "/home/stas/NotOnlyFansBot/venv/lib/python3.10/site-packages/aiogram/bot/base.py", line 236, in request
    return await api.make_request(await self.get_session(), self.server, self.__token, method, data, files,
  File "/home/stas/NotOnlyFansBot/venv/lib/python3.10/site-packages/aiogram/bot/api.py", line 140, in make_request
    return check_result(method, response.content_type, response.status, await response.text())
  File "/home/stas/NotOnlyFansBot/venv/lib/python3.10/site-packages/aiogram/bot/api.py", line 119, in check_result
    exceptions.ConflictError.detect(description)
  File "/home/stas/NotOnlyFansBot/venv/lib/python3.10/site-packages/aiogram/utils/exceptions.py", line 140, in detect
    raise err(cls.text or description)
aiogram.utils.exceptions.TerminatedByOtherGetUpdates: Terminated by other getupdates request; make sure that only one bot instance is running
2023-09-12 23:50:41,765 - ERROR - dispatcher.py:390 - Cause exception while getting updates.
Traceback (most recent call last):
  File "/home/stas/NotOnlyFansBot/venv/lib/python3.10/site-packages/aiogram/dispatcher/dispatcher.py", line 381, in start_polling
    updates = await self.bot.get_updates(
  File "/home/stas/NotOnlyFansBot/venv/lib/python3.10/site-packages/aiogram/bot/bot.py", line 110, in get_updates
    result = await self.request(api.Methods.GET_UPDATES, payload)
  File "/home/stas/NotOnlyFansBot/venv/lib/python3.10/site-packages/aiogram/bot/base.py", line 236, in request
    return await api.make_request(await self.get_session(), self.server, self.__token, method, data, files,
  File "/home/stas/NotOnlyFansBot/venv/lib/python3.10/site-packages/aiogram/bot/api.py", line 140, in make_request
    return check_result(method, response.content_type, response.status, await response.text())
  File "/home/stas/NotOnlyFansBot/venv/lib/python3.10/site-packages/aiogram/bot/api.py", line 119, in check_result
    exceptions.ConflictError.detect(description)
  File "/home/stas/NotOnlyFansBot/venv/lib/python3.10/site-packages/aiogram/utils/exceptions.py", line 140, in detect
    raise err(cls.text or description)
aiogram.utils.exceptions.TerminatedByOtherGetUpdates: Terminated by other getupdates request; make sure that only one bot instance is running
2023-09-12 23:50:51,881 - ERROR - dispatcher.py:390 - Cause exception while getting updates.
Traceback (most recent call last):
  File "/home/stas/NotOnlyFansBot/venv/lib/python3.10/site-packages/aiogram/dispatcher/dispatcher.py", line 381, in start_polling
    updates = await self.bot.get_updates(
  File "/home/stas/NotOnlyFansBot/venv/lib/python3.10/site-packages/aiogram/bot/bot.py", line 110, in get_updates
    result = await self.request(api.Methods.GET_UPDATES, payload)
  File "/home/stas/NotOnlyFansBot/venv/lib/python3.10/site-packages/aiogram/bot/base.py", line 236, in request
    return await api.make_request(await self.get_session(), self.server, self.__token, method, data, files,
  File "/home/stas/NotOnlyFansBot/venv/lib/python3.10/site-packages/aiogram/bot/api.py", line 140, in make_request
    return check_result(method, response.content_type, response.status, await response.text())
  File "/home/stas/NotOnlyFansBot/venv/lib/python3.10/site-packages/aiogram/bot/api.py", line 119, in check_result
    exceptions.ConflictError.detect(description)
  File "/home/stas/NotOnlyFansBot/venv/lib/python3.10/site-packages/aiogram/utils/exceptions.py", line 140, in detect
    raise err(cls.text or description)
aiogram.utils.exceptions.TerminatedByOtherGetUpdates: Terminated by other getupdates request; make sure that only one bot instance is running
2023-09-12 23:51:02,005 - ERROR - dispatcher.py:390 - Cause exception while getting updates.
Traceback (most recent call last):
  File "/home/stas/NotOnlyFansBot/venv/lib/python3.10/site-packages/aiogram/dispatcher/dispatcher.py", line 381, in start_polling
    updates = await self.bot.get_updates(
  File "/home/stas/NotOnlyFansBot/venv/lib/python3.10/site-packages/aiogram/bot/bot.py", line 110, in get_updates
    result = await self.request(api.Methods.GET_UPDATES, payload)
  File "/home/stas/NotOnlyFansBot/venv/lib/python3.10/site-packages/aiogram/bot/base.py", line 236, in request
    return await api.make_request(await self.get_session(), self.server, self.__token, method, data, files,
  File "/home/stas/NotOnlyFansBot/venv/lib/python3.10/site-packages/aiogram/bot/api.py", line 140, in make_request
    return check_result(method, response.content_type, response.status, await response.text())
  File "/home/stas/NotOnlyFansBot/venv/lib/python3.10/site-packages/aiogram/bot/api.py", line 119, in check_result
    exceptions.ConflictError.detect(description)
  File "/home/stas/NotOnlyFansBot/venv/lib/python3.10/site-packages/aiogram/utils/exceptions.py", line 140, in detect
    raise err(cls.text or description)
aiogram.utils.exceptions.TerminatedByOtherGetUpdates: Terminated by other getupdates request; make sure that only one bot instance is running
2023-09-12 23:51:12,129 - ERROR - dispatcher.py:390 - Cause exception while getting updates.
Traceback (most recent call last):
  File "/home/stas/NotOnlyFansBot/venv/lib/python3.10/site-packages/aiogram/dispatcher/dispatcher.py", line 381, in start_polling
    updates = await self.bot.get_updates(
  File "/home/stas/NotOnlyFansBot/venv/lib/python3.10/site-packages/aiogram/bot/bot.py", line 110, in get_updates
    result = await self.request(api.Methods.GET_UPDATES, payload)
  File "/home/stas/NotOnlyFansBot/venv/lib/python3.10/site-packages/aiogram/bot/base.py", line 236, in request
    return await api.make_request(await self.get_session(), self.server, self.__token, method, data, files,
  File "/home/stas/NotOnlyFansBot/venv/lib/python3.10/site-packages/aiogram/bot/api.py", line 140, in make_request
    return check_result(method, response.content_type, response.status, await response.text())
  File "/home/stas/NotOnlyFansBot/venv/lib/python3.10/site-packages/aiogram/bot/api.py", line 119, in check_result
    exceptions.ConflictError.detect(description)
  File "/home/stas/NotOnlyFansBot/venv/lib/python3.10/site-packages/aiogram/utils/exceptions.py", line 140, in detect
    raise err(cls.text or description)
aiogram.utils.exceptions.TerminatedByOtherGetUpdates: Terminated by other getupdates request; make sure that only one bot instance is running
2023-09-12 23:51:22,256 - ERROR - dispatcher.py:390 - Cause exception while getting updates.
Traceback (most recent call last):
  File "/home/stas/NotOnlyFansBot/venv/lib/python3.10/site-packages/aiogram/dispatcher/dispatcher.py", line 381, in start_polling
    updates = await self.bot.get_updates(
  File "/home/stas/NotOnlyFansBot/venv/lib/python3.10/site-packages/aiogram/bot/bot.py", line 110, in get_updates
    result = await self.request(api.Methods.GET_UPDATES, payload)
  File "/home/stas/NotOnlyFansBot/venv/lib/python3.10/site-packages/aiogram/bot/base.py", line 236, in request
    return await api.make_request(await self.get_session(), self.server, self.__token, method, data, files,
  File "/home/stas/NotOnlyFansBot/venv/lib/python3.10/site-packages/aiogram/bot/api.py", line 140, in make_request
    return check_result(method, response.content_type, response.status, await response.text())
  File "/home/stas/NotOnlyFansBot/venv/lib/python3.10/site-packages/aiogram/bot/api.py", line 119, in check_result
    exceptions.ConflictError.detect(description)
  File "/home/stas/NotOnlyFansBot/venv/lib/python3.10/site-packages/aiogram/utils/exceptions.py", line 140, in detect
    raise err(cls.text or description)
aiogram.utils.exceptions.TerminatedByOtherGetUpdates: Terminated by other getupdates request; make sure that only one bot instance is running
2023-09-12 23:51:32,373 - ERROR - dispatcher.py:390 - Cause exception while getting updates.
Traceback (most recent call last):
  File "/home/stas/NotOnlyFansBot/venv/lib/python3.10/site-packages/aiogram/dispatcher/dispatcher.py", line 381, in start_polling
    updates = await self.bot.get_updates(
  File "/home/stas/NotOnlyFansBot/venv/lib/python3.10/site-packages/aiogram/bot/bot.py", line 110, in get_updates
    result = await self.request(api.Methods.GET_UPDATES, payload)
  File "/home/stas/NotOnlyFansBot/venv/lib/python3.10/site-packages/aiogram/bot/base.py", line 236, in request
    return await api.make_request(await self.get_session(), self.server, self.__token, method, data, files,
  File "/home/stas/NotOnlyFansBot/venv/lib/python3.10/site-packages/aiogram/bot/api.py", line 140, in make_request
    return check_result(method, response.content_type, response.status, await response.text())
  File "/home/stas/NotOnlyFansBot/venv/lib/python3.10/site-packages/aiogram/bot/api.py", line 119, in check_result
    exceptions.ConflictError.detect(description)
  File "/home/stas/NotOnlyFansBot/venv/lib/python3.10/site-packages/aiogram/utils/exceptions.py", line 140, in detect
    raise err(cls.text or description)
aiogram.utils.exceptions.TerminatedByOtherGetUpdates: Terminated by other getupdates request; make sure that only one bot instance is running
2023-09-12 23:51:42,489 - ERROR - dispatcher.py:390 - Cause exception while getting updates.
Traceback (most recent call last):
  File "/home/stas/NotOnlyFansBot/venv/lib/python3.10/site-packages/aiogram/dispatcher/dispatcher.py", line 381, in start_polling
    updates = await self.bot.get_updates(
  File "/home/stas/NotOnlyFansBot/venv/lib/python3.10/site-packages/aiogram/bot/bot.py", line 110, in get_updates
    result = await self.request(api.Methods.GET_UPDATES, payload)
  File "/home/stas/NotOnlyFansBot/venv/lib/python3.10/site-packages/aiogram/bot/base.py", line 236, in request
    return await api.make_request(await self.get_session(), self.server, self.__token, method, data, files,
  File "/home/stas/NotOnlyFansBot/venv/lib/python3.10/site-packages/aiogram/bot/api.py", line 140, in make_request
    return check_result(method, response.content_type, response.status, await response.text())
  File "/home/stas/NotOnlyFansBot/venv/lib/python3.10/site-packages/aiogram/bot/api.py", line 119, in check_result
    exceptions.ConflictError.detect(description)
  File "/home/stas/NotOnlyFansBot/venv/lib/python3.10/site-packages/aiogram/utils/exceptions.py", line 140, in detect
    raise err(cls.text or description)
aiogram.utils.exceptions.TerminatedByOtherGetUpdates: Terminated by other getupdates request; make sure that only one bot instance is running
